Workbook

Sheet 📊 Dashboard
B2: 🤖 AI / ML ENGINEER – 12-MONTH STREAK TRACKER
B3: 336 Days · 8 Phases · 48 Weeks | Tick ✓ each day you complete on the tracker sheet
B5: DAYS DONE | D5: DAYS LEFT | F5: CURRENT STREAK | H5: BEST STREAK | J5: % COMPLETE
B6: ='📅 Tracker'!P2 -> 14 | D6: ='📅 Tracker'!P3 -> 322 | F6: ='📅 Tracker'!P4 -> 14 | H6: ='📅 Tracker'!P5 -> 14 | J6: ='📅 Tracker'!P6 -> 4.1666667
B9: PHASE | C9: PHASE NAME | E9: MONTHS | G9: DAYS | H9: DONE | I9: PROGRESS
B10: Phase 1 | C10: Python Foundations | E10: Months 1–2 | G10: 56 | H10: =COUNTIFS('📅 Tracker'!G:G,"Phase 1",'📅 Tracker'!H:H,"✓") -> 14 | I10: =IFERROR(H10/56,0) -> 0.25
B11: Phase 2 | C11: Data Analysis | E11: Month 3 | G11: 28 | H11: =COUNTIFS('📅 Tracker'!G:G,"Phase 2",'📅 Tracker'!H:H,"✓") -> 0 | I11: =IFERROR(H11/28,0) -> 0
B12: Phase 3 | C12: Math for AI | E12: Month 4 | G12: 28 | H12: =COUNTIFS('📅 Tracker'!G:G,"Phase 3",'📅 Tracker'!H:H,"✓") -> 0 | I12: =IFERROR(H12/28,0) -> 0
B13: Phase 4 | C13: Machine Learning | E13: Months 5–6 | G13: 56 | H13: =COUNTIFS('📅 Tracker'!G:G,"Phase 4",'📅 Tracker'!H:H,"✓") -> 0 | I13: =IFERROR(H13/56,0) -> 0
B14: Phase 5 | C14: Deep Learning | E14: Months 7–8 | G14: 56 | H14: =COUNTIFS('📅 Tracker'!G:G,"Phase 5",'📅 Tracker'!H:H,"✓") -> 0 | I14: =IFERROR(H14/56,0) -> 0
B15: Phase 6 | C15: GenAI & Transformers | E15: Months 9–10 | G15: 56 | H15: =COUNTIFS('📅 Tracker'!G:G,"Phase 6",'📅 Tracker'!H:H,"✓") -> 0 | I15: =IFERROR(H15/56,0) -> 0
B16: Phase 7 | C16: Engineering Stack | E16: Month 11 | G16: 28 | H16: =COUNTIFS('📅 Tracker'!G:G,"Phase 7",'📅 Tracker'!H:H,"✓") -> 0 | I16: =IFERROR(H16/28,0) -> 0
B17: Phase 8 | C17: Projects & Job Prep | E17: Month 12 | G17: 28 | H17: =COUNTIFS('📅 Tracker'!G:G,"Phase 8",'📅 Tracker'!H:H,"✓") -> 0 | I17: =IFERROR(H17/28,0) -> 0
B20: 📌 HOW TO USE: Go to the '📅 Tracker' sheet → find today's row → type ✓ in the DONE column (H) → watch your stats update!
B21: 💡 TIP: You can also type ✗ for a missed day or leave blank. Streak counts consecutive ✓ from Day 1.

Sheet 📅 Tracker
B1: 🤖 AI / ML ENGINEER ROADMAP – DAILY TRACKER | P1: STATS (do not edit)
B2: DAY | C2: WEEK | D2: PHASE | E2: MONTH | F2: PHASE NAME | G2: TOPIC | H2: PHASE # | I2: DONE | J2: WHAT TO STUDY TODAY | O2: Days Done | P2: =COUNTIF(H3:H402,"✓") -> 14
B3: 1 | C3: Wk 1 Mon | D3: 1 | E3: Months 1–2 | F3: Python Foundations | G3: Phase 1 | H3: ✓ | I3: Day 1: Python syntax & indentation | J3: Helsinki MOOC → https://programming-mooc.fi | Corey Schafer OOP → youtube.com/playlist?list=PL-osiE80TeTsqhIuOqKhwlXsIBIdSeYtc | O3: Days Left | P3: =336-P2 -> 322 | R3: 46074 | S3: start
B4: 2 | C4: Wk 1 Tue | D4: 1 | E4: Months 1–2 | F4: Python Foundations | G4: Phase 1 | H4: ✓ | I4: Day 2: Variables & data types | J4: Helsinki MOOC → https://programming-mooc.fi | Corey Schafer OOP → youtube.com/playlist?list=PL-osiE80TeTsqhIuOqKhwlXsIBIdSeYtc | O4: Current Streak | P4: =IFERROR(MATCH(FALSE(),EXACT(H3:H338,"✓"),0)-1,COUNTIF(H3:H338,"✓")) -> 14 | R4: 46410 | S4: end
B5: 3 | C5: Wk 1 Wed | D5: 1 | E5: Months 1–2 | F5: Python Foundations | G5: Phase 1 | H5: ✓ | I5: Day 3: Operators (arithmetic, comparison, logical) | J5: Helsinki MOOC → https://programming-mooc.fi | Corey Schafer OOP → youtube.com/playlist?list=PL-osiE80TeTsqhIuOqKhwlXsIBIdSeYtc | O5: Best Streak (approx) | P5: =P2 -> 14
B6: 4 | C6: Wk 1 Thu | D6: 1 | E6: Months 1–2 | F6: Python Foundations | G6: Phase 1 | H6: ✓ | I6: Day 4: Input / Output – input() & print() | J6: Helsinki MOOC → https://programming-mooc.fi | Corey Schafer OOP → youtube.com/playlist?list=PL-osiE80TeTsqhIuOqKhwlXsIBIdSeYtc | O6: % Complete | P6: =IFERROR(P2/336*100,0) -> 4.1666667
B7: 5 | C7: Wk 1 Fri | D7: 1 | E7: Months 1–2 | F7: Python Foundations | G7: Phase 1 | H7: ✓ | I7: Day 5: Practice: basic calculator | J7: Helsinki MOOC → https://programming-mooc.fi | Corey Schafer OOP → youtube.com/playlist?list=PL-osiE80TeTsqhIuOqKhwlXsIBIdSeYtc
B8: 6 | C8: Wk 1 Sat | D8: 1 | E8: Months 1–2 | F8: Python Foundations | G8: Phase 1 | H8: ✓ | I8: Day 6: Mini exercises (HackerRank) | J8: Helsinki MOOC → https://programming-mooc.fi | Corey Schafer OOP → youtube.com/playlist?list=PL-osiE80TeTsqhIuOqKhwlXsIBIdSeYtc
B9: 7 | C9: Wk 1 Sun | D9: 1 | E9: Months 1–2 | F9: Python Foundations | G9: Phase 1 | H9: ✓ | I9: Day 7: Review & push to GitHub | J9: Helsinki MOOC → https://programming-mooc.fi | Corey Schafer OOP → youtube.com/playlist?list=PL-osiE80TeTsqhIuOqKhwlXsIBIdSeYtc
B11: 8 | C11: Wk 2 Mon | D11: 1 | E11: Months 1–2 | F11: Python Foundations | G11: Phase 1 | H11: ✓ | I11: Day 8: if / elif / else statements | J11: Helsinki MOOC → https://programming-mooc.fi | Corey Schafer OOP → youtube.com/playlist?list=PL-osiE80TeTsqhIuOqKhwlXsIBIdSeYtc
B12: 9 | C12: Wk 2 Tue | D12: 1 | E12: Months 1–2 | F12: Python Foundations | G12: Phase 1 | H12: ✓ | I12: Day 9: for loop & range() | J12: Helsinki MOOC → https://programming-mooc.fi | Corey Schafer OOP → youtube.com/playlist?list=PL-osiE80TeTsqhIuOqKhwlXsIBIdSeYtc
B13: 10 | C13: Wk 2 Wed | D13: 1 | E13: Months 1–2 | F13: Python Foundations | G13: Phase 1 | H13: ✓ | I13: Day 10: while loop | J13: Helsinki MOOC → https://programming-mooc.fi | Corey Schafer OOP → youtube.com/playlist?list=PL-osiE80TeTsqhIuOqKhwlXsIBIdSeYtc
B14: 11 | C14: Wk 2 Thu | D14: 1 | E14: Months 1–2 | F14: Python Foundations | G14: Phase 1 | H14: ✓ | I14: Day 11: break, continue, pass | J14: Helsinki MOOC → https://programming-mooc.fi | Corey Schafer OOP → youtube.com/playlist?list=PL-osiE80TeTsqhIuOqKhwlXsIBIdSeYtc
B15: 12 | C15: Wk 2 Fri | D15: 1 | E15: Months 1–2 | F15: Python Foundations | G15: Phase 1 | H15: ✓ | I15: Day 12: Nested loops practice | J15: Helsinki MOOC → https://programming-mooc.fi | Corey Schafer OOP → youtube.com/playlist?list=PL-osiE80TeTsqhIuOqKhwlXsIBIdSeYtc
B16: 13 | C16: Wk 2 Sat | D16: 1 | E16: Months 1–2 | F16: Python Foundations | G16: Phase 1 | H16: ✓ | I16: Day 13: Pattern printing exercises | J16: Helsinki MOOC → https://programming-mooc.fi | Corey Schafer OOP → youtube.com/playlist?list=PL-osiE80TeTsqhIuOqKhwlXsIBIdSeYtc
B17: 14 | C17: Wk 2 Sun | D17: 1 | E17: Months 1–2 | F17: Python Foundations | G17: Phase 1 | H17: ✓ | I17: Day 14: HackerRank Flow Control | J17: Helsinki MOOC → https://programming-mooc.fi | Corey Schafer OOP → youtube.com/playlist?list=PL-osiE80TeTsqhIuOqKhwlXsIBIdSeYtc
B19: 15 | C19: Wk 3 Mon | D19: 1 | E19: Months 1–2 | F19: Python Foundations | G19: Phase 1 | I19: Day 15: def – defining functions | J19: Helsinki MOOC → https://programming-mooc.fi | Corey Schafer OOP → youtube.com/playlist?list=PL-osiE80TeTsqhIuOqKhwlXsIBIdSeYtc
B20: 16 | C20: Wk 3 Tue | D20: 1 | E20: Months 1–2 | F20: Python Foundations | G20: Phase 1 | I20: Day 16: Arguments & default values | J20: Helsinki MOOC → https://programming-mooc.fi | Corey Schafer OOP → youtube.com/playlist?list=PL-osiE80TeTsqhIuOqKhwlXsIBIdSeYtc
B21: 17 | C21: Wk 3 Wed | D21: 1 | E21: Months 1–2 | F21: Python Foundations | G21: Phase 1 | I21: Day 17: Return values | J21: Helsinki MOOC → https://programming-mooc.fi | Corey Schafer OOP → youtube.com/playlist?list=PL-osiE80TeTsqhIuOqKhwlXsIBIdSeYtc
B22: 18 | C22: Wk 3 Thu | D22: 1 | E22: Months 1–2 | F22: Python Foundations | G22: Phase 1 | I22: Day 18: Lambda functions | J22: Helsinki MOOC → https://programming-mooc.fi | Corey Schafer OOP → youtube.com/playlist?list=PL-osiE80TeTsqhIuOqKhwlXsIBIdSeYtc
B23: 19 | C23: Wk 3 Fri | D23: 1 | E23: Months 1–2 | F23: Python Foundations | G23: Phase 1 | I23: Day 19: *args & **kwargs | J23: Helsinki MOOC → https://programming-mooc.fi | Corey Schafer OOP → youtube.com/playlist?list=PL-osiE80TeTsqhIuOqKhwlXsIBIdSeYtc
B24: 20 | C24: Wk 3 Sat | D24: 1 | E24: Months 1–2 | F24: Python Foundations | G24: Phase 1 | I24: Day 20: Scope: local vs global | J24: Helsinki MOOC → https://programming-mooc.fi | Corey Schafer OOP → youtube.com/playlist?list=PL-osiE80TeTsqhIuOqKhwlXsIBIdSeYtc
B25: 21 | C25: Wk 3 Sun | D25: 1 | E25: Months 1–2 | F25: Python Foundations | G25: Phase 1 | I25: Day 21: Function exercises | J25: Helsinki MOOC → https://programming-mooc.fi | Corey Schafer OOP → youtube.com/playlist?list=PL-osiE80TeTsqhIuOqKhwlXsIBIdSeYtc
B27: 22 | C27: Wk 4 Mon | D27: 1 | E27: Months 1–2 | F27: Python Foundations | G27: Phase 1 | I27: Day 22: Lists – create, index, slice | J27: Helsinki MOOC → https://programming-mooc.fi | Corey Schafer OOP → youtube.com/playlist?list=PL-osiE80TeTsqhIuOqKhwlXsIBIdSeYtc
B28: 23 | C28: Wk 4 Tue | D28: 1 | E28: Months 1–2 | F28: Python Foundations | G28: Phase 1 | I28: Day 23: Tuples & immutability | J28: Helsinki MOOC → https://programming-mooc.fi | Corey Schafer OOP → youtube.com/playlist?list=PL-osiE80TeTsqhIuOqKhwlXsIBIdSeYtc
B29: 24 | C29: Wk 4 Wed | D29: 1 | E29: Months 1–2 | F29: Python Foundations | G29: Phase 1 | I29: Day 24: Sets & set operations | J29: Helsinki MOOC → https://programming-mooc.fi | Corey Schafer OOP → youtube.com/playlist?list=PL-osiE80TeTsqhIuOqKhwlXsIBIdSeYtc
B30: 25 | C30: Wk 4 Thu | D30: 1 | E30: Months 1–2 | F30: Python Foundations | G30: Phase 1 | I30: Day 25: Dictionaries – CRUD | J30: Helsinki MOOC → https://programming-mooc.fi | Corey Schafer OOP → youtube.com/playlist?list=PL-osiE80TeTsqhIuOqKhwlXsIBIdSeYtc
B31: 26 | C31: Wk 4 Fri | D31: 1 | E31: Months 1–2 | F31: Python Foundations | G31: Phase 1 | I31: Day 26: List comprehensions | J31: Helsinki MOOC → https://programming-mooc.fi | Corey Schafer OOP → youtube.com/playlist?list=PL-osiE80TeTsqhIuOqKhwlXsIBIdSeYtc
... B65: 56 | C65: Wk 8 Sun | D65: 1 | E65: Months 1–2 | F65: Python Foundations | G65: Phase 1 | I65: Day 56: PROJECT: Library Management System | J65: Helsinki MOOC → https://programming-mooc.fi | Corey Schafer OOP → youtube.com/playlist?list=PL-osiE80TeTsqhIuOqKhwlXsIBIdSeYtc
B67: ▲ END OF PHASE 1: Python Foundations ▲
B69: 57 | C69: Wk 9 Mon | D69: 2 | E69: Month 3 | F69: Data Analysis | G69: Phase 2 | I69: Day 57: NumPy – arrays vs Python lists | J69: Kaggle Learn Pandas → kaggle.com/learn/pandas | freeCodeCamp Data Analysis → youtube.com/watch?v=r-uOLxNrNk8
B70: 58 | C70: Wk 9 Tue | D70: 2 | E70: Month 3 | F70: Data Analysis | G70: Phase 2 | I70: Day 58: Array creation: zeros, ones, arange, linspace | J70: Kaggle Learn Pandas → kaggle.com/learn/pandas | freeCodeCamp Data Analysis → youtube.com/watch?v=r-uOLxNrNk8
B71: 59 | C71: Wk 9 Wed | D71: 2 | E71: Month 3 | F71: Data Analysis | G71: Phase 2 | I71: Day 59: Indexing & slicing | J71: Kaggle Learn Pandas → kaggle.com/learn/pandas | freeCodeCamp Data Analysis → youtube.com/watch?v=r-uOLxNrNk8
B72: 60 | C72: Wk 9 Thu | D72: 2 | E72: Month 3 | F72: Data Analysis | G72: Phase 2 | I72: Day 60: Array reshaping | J72: Kaggle Learn Pandas → kaggle.com/learn/pandas | freeCodeCamp Data Analysis → youtube.com/watch?v=r-uOLxNrNk8
B73: 61 | C73: Wk 9 Fri | D73: 2 | E73: Month 3 | F73: Data Analysis | G73: Phase 2 | I73: Day 61: Broadcasting rules | J73: Kaggle Learn Pandas → kaggle.com/learn/pandas | freeCodeCamp Data Analysis → youtube.com/watch?v=r-uOLxNrNk8
B74: 62 | C74: Wk 9 Sat | D74: 2 | E74: Month 3 | F74: Data Analysis | G74: Phase 2 | I74: Day 62: Vector & matrix operations | J74: Kaggle Learn Pandas → kaggle.com/learn/pandas | freeCodeCamp Data Analysis → youtube.com/watch?v=r-uOLxNrNk8
B75: 63 | C75: Wk 9 Sun | D75: 2 | E75: Month 3 | F75: Data Analysis | G75: Phase 2 | I75: Day 63: Kaggle NumPy exercises | J75: Kaggle Learn Pandas → kaggle.com/learn/pandas | freeCodeCamp Data Analysis → youtube.com/watch?v=r-uOLxNrNk8
B77: 64 | C77: Wk 10 Mon | D77: 2 | E77: Month 3 | F77: Data Analysis | G77: Phase 2 | I77: Day 64: Pandas – Series basics | J77: Kaggle Learn Pandas → kaggle.com/learn/pandas | freeCodeCamp Data Analysis → youtube.com/watch?v=r-uOLxNrNk8
B78: 65 | C78: Wk 10 Tue | D78: 2 | E78: Month 3 | F78: Data Analysis | G78: Phase 2 | I78: Day 65: Pandas – DataFrame basics | J78: Kaggle Learn Pandas → kaggle.com/learn/pandas | freeCodeCamp Data Analysis → youtube.com/watch?v=r-uOLxNrNk8
B79: 66 | C79: Wk 10 Wed | D79: 2 | E79: Month 3 | F79: Data Analysis | G79: Phase 2 | I79: Day 66: Reading CSV / Excel / JSON | J79: Kaggle Learn Pandas → kaggle.com/learn/pandas | freeCodeCamp Data Analysis → youtube.com/watch?v=r-uOLxNrNk8
...

Sheet 📚 Resources
B1: 📚 RESOURCES QUICK REFERENCE
B2: # | C2: Phase | D2: Duration | E2: Primary Resource | F2: URL | G2: Project
B3: 1 | C3: Python Foundations | D3: Months 1–2 | E3: Helsinki MOOC + Corey Schafer OOP | F3: https://programming-mooc.fi | youtube.com/playlist?list=PL-osiE80TeTsqhIuOqKhwlXsIBIdSeYtc | G3: Library Management System
B4: 2 | C4: Data Analysis | D4: Month 3 | E4: Kaggle Learn Pandas + freeCodeCamp | F4: https://kaggle.com/learn/pandas | youtube.com/watch?v=r-uOLxNrNk8 | G4: Sales Data Dashboard
B5: 3 | C5: Math for AI | D5: Month 4 | E5: StatQuest (YouTube) + Khan Academy | F5: https://youtube.com/c/joshstarmer | khanacademy.org/math/statistics-probability | G5: Statistical Analysis Report
B6: 4 | C6: Machine Learning | D6: Months 5–6 | E6: Andrew Ng ML Specialization (Coursera) | F6: https://coursera.org/specializations/machine-learning-introduction | G6: House Price Prediction + Customer Segmentation
B7: 5 | C7: Deep Learning | D7: Months 7–8 | E7: DeepLearning.AI + TF/PyTorch Tutorials | F7: https://coursera.org/specializations/deep-learning | tensorflow.org/tutorials | G7: Digit Recognition + Image Classifier
B8: 6 | C8: GenAI & Transformers | D8: Months 9–10 | E8: Hugging Face NLP + DeepLearning.AI Courses | F8: https://huggingface.co/learn/nlp-course | deeplearning.ai/short-courses | G8: GenAI Assistant (RAG + Agents)
B9: 7 | C9: Engineering Stack | D9: Month 11 | E9: freeCodeCamp Flask + TechWorld w/ Nana | F9: https://youtube.com/watch?v=Qr4QMBUPxWo | youtube.com/watch?v=3c-iBn73dDE | G9: AI Web Application (End-to-End)
B10: 8 | C10: Projects & Job Prep | D10: Month 12 | E10: Kaggle Competitions + LeetCode | F10: https://kaggle.com/competitions | leetcode.com | G10: Industry-Grade GenAI System (Capstone)
